<mujoco model="fr3">
  <compiler angle="radian" meshdir="assets" />

  <option integrator="implicitfast" />

  <default>
    <default class="fr3">
      <joint damping="0.21" armature="0.195" frictionloss="1.137" />
      <position inheritrange="1" />

      <default class="visual">
        <geom type="mesh" group="2" contype="0" conaffinity="0" />
      </default>

      <default class="collision">
        <geom group="3" contype="0" conaffinity="2" mass="0" density="0" />
      </default>

      <default class="fr3_vel">
        <velocity ctrllimited="true" kv="50" />
      </default>

      <site size="0.001" rgba="0.5 0.5 0.5 0.3" group="4" />
    </default>
  </default>


  <asset>
    <material name="black" rgba=".2 .2 .2 1" />
    <material name="white" rgba="1 1 1 1" />
    <material name="red" rgba="1 0.072272 0.039546 1" />
    <material name="gray" rgba="0.863156 0.863156 0.863157 1" />
    <material name="button_green" rgba="0.102241 0.571125 0.102242 1" />
    <material name="button_red" rgba="0.520996 0.008023 0.013702 1" />
    <material name="button_blue" rgba="0.024157 0.445201 0.737911 1" />

    <mesh file="link0_0.obj" />
    <mesh file="link0_1.obj" />
    <mesh file="link0_2.obj" />
    <mesh file="link0_3.obj" />
    <mesh file="link0_4.obj" />
    <mesh file="link0_5.obj" />
    <mesh file="link0_6.obj" />
    <mesh file="link1.obj" />
    <mesh file="link2.obj" />
    <mesh file="link3_0.obj" />
    <mesh file="link3_1.obj" />
    <mesh file="link4_0.obj" />
    <mesh file="link4_1.obj" />
    <mesh file="link5_0.obj" />
    <mesh file="link5_1.obj" />
    <mesh file="link5_2.obj" />
    <mesh file="link6_0.obj" />
    <mesh file="link6_1.obj" />
    <mesh file="link6_2.obj" />
    <mesh file="link6_3.obj" />
    <mesh file="link6_4.obj" />
    <mesh file="link6_5.obj" />
    <mesh file="link6_6.obj" />
    <mesh file="link6_7.obj" />
    <mesh file="link7_0.obj" />
    <mesh file="link7_1.obj" />
    <mesh file="link7_2.obj" />
    <mesh file="link7_3.obj" />

    <mesh name="link0_coll" file="link0.stl" />
    <mesh name="link1_coll" file="link1.stl" />
    <mesh name="link2_coll" file="link2.stl" />
    <mesh name="link3_coll" file="link3.stl" />
    <mesh name="link4_coll" file="link4.stl" />
    <mesh name="link5_coll" file="link5.stl" />
    <mesh name="link6_coll" file="link6.stl" />
    <mesh name="link7_coll" file="link7.stl" />
  </asset>

  <worldbody>
    <body name="base" childclass="fr3" gravcomp="1">
      <body name="fr3_link0" pos="0.0 0.0 0.0" gravcomp="1">
        <geom mesh="link0_0" material="black" class="visual" />
        <geom mesh="link0_1" material="white" class="visual" />
        <geom mesh="link0_2" material="white" class="visual" />
        <geom mesh="link0_3" material="white" class="visual" />
        <geom mesh="link0_4" material="white" class="visual" />
        <geom mesh="link0_5" material="red" class="visual" />
        <geom mesh="link0_6" material="black" class="visual" />
        <!-- <geom name="fr3_link0_collision" mesh="link0_coll" class="collision"/> -->
        <geom
                    type="capsule"
                    fromto="0.0 0 0.2  0.0 0 0.08"
                    size="0.06"
                    class="collision"
                /> <!-- MJX -->
        <body name="fr3_link1" pos="0 0 0.333" gravcomp="1">
          <inertial
                        pos="4.128e-07 -0.0181251 -0.0386036"
                        quat="0.998098 -0.0605364 0.00380499 0.0110109"
                        mass="2.92747"
                        diaginertia="0.0239286 0.0227246 0.00610634"
                    />
          <joint
                        name="fr3_joint1"
                        axis="0 0 1"
                        range="-2.7437 2.7437"
                        actuatorfrcrange="-87 87"
                    />
          <!-- <geom name="fr3_link1_collision" class="collision" mesh="link1_coll"/> -->
          <geom
                        type="capsule"
                        fromto="0 -0.08 0  0 0.08 0"
                        size="0.06"
                        class="collision"
                    /> <!-- MJX -->
          <geom material="white" mesh="link1" class="visual" />
          <body name="fr3_link2" quat="1 -1 0 0" gravcomp="1">
            <inertial
                            pos="0.00318289 -0.0743222 0.00881461"
                            quat="0.502599 0.584437 -0.465998 0.434366"
                            mass="2.93554"
                            diaginertia="0.0629567 0.0411924 0.0246371"
                        />
            <joint
                            name="fr3_joint2"
                            axis="0 0 1"
                            range="-1.7837 1.7837"
                            actuatorfrcrange="-87 87"
                        />
            <geom material="white" mesh="link2" class="visual" />
            <!-- <geom name="fr3_link2_collision" class="collision" mesh="link2_coll"/> -->
            <geom
                            type="capsule"
                            fromto="0 -0.20 0  0 -0.14 0"
                            size="0.07"
                            class="collision"
                        /> <!-- MJX -->
            <body name="fr3_link3" pos="0 -0.316 0" quat="1 1 0 0" gravcomp="1">
              <inertial
                                pos="0.0407016 -0.00482006 -0.0289731"
                                quat="0.921025 -0.244161 0.155272 0.260745"
                                mass="2.2449"
                                diaginertia="0.0267409 0.0189869 0.0171587"
                            />
              <joint
                                name="fr3_joint3"
                                axis="0 0 1"
                                range="-2.9007 2.9007"
                                actuatorfrcrange="-87 87"
                            />
              <geom mesh="link3_0" material="white" class="visual" />
              <geom mesh="link3_1" material="black" class="visual" />
              <!-- <geom name="fr3_link3_collision" class="collision" mesh="link3_coll"/> -->
              <body
                                name="fr3_link4"
                                pos="0.0825 0 0"
                                quat="1 1 0 0"
                                gravcomp="1"
                            >
                <inertial
                                    pos="-0.0459101 0.0630493 -0.00851879"
                                    quat="0.438018 0.803311 0.00937812 0.403414"
                                    mass="2.6156"
                                    diaginertia="0.05139 0.0372717 0.0160047"
                                />
                <joint
                                    name="fr3_joint4"
                                    axis="0 0 1"
                                    range="-3.0421 -0.1518"
                                    actuatorfrcrange="-87 87"
                                />
                <geom mesh="link4_0" material="white" class="visual" />
                <geom mesh="link4_1" material="black" class="visual" />
                <!-- <geom name="fr3_link4_collision" class="collision" mesh="link4_coll"/> -->
                <body
                                    name="fr3_link5"
                                    pos="-0.0825 0.384 0"
                                    quat="1 -1 0 0"
                                    gravcomp="1"
                                >
                  <inertial
                                        pos="-0.00160396 0.0292536 -0.0972966"
                                        quat="0.919031 0.125604 0.0751531 -0.366003"
                                        mass="2.32712"
                                        diaginertia="0.0579335 0.0449144 0.0130634"
                                    />
                  <joint
                                        name="fr3_joint5"
                                        axis="0 0 1"
                                        range="-2.8065 2.8065"
                                        actuatorfrcrange="-12 12"
                                        armature="0.074"
                                        frictionloss="0.763"
                                    />
                  <geom
                                        type="capsule"
                                        fromto="0 0 -0.335  0 0 -0.215"
                                        size="0.06"
                                        class="collision"
                                    /> <!-- MJX -->
                  <geom mesh="link5_0" material="white" class="visual" />
                  <geom mesh="link5_1" material="white" class="visual" />
                  <geom mesh="link5_2" material="black" class="visual" />
                  <!-- <geom name="fr3_link5_collision" class="collision" mesh="link5_coll"/> -->
                  <body name="fr3_link6" quat="1 1 0 0" gravcomp="1">
                    <inertial
                                            pos="0.0597131 -0.0410295 -0.0101693"
                                            quat="0.621301 0.552665 0.510011 0.220081"
                                            mass="1.81704"
                                            diaginertia="0.0175039 0.0161123 0.00193529"
                                        />
                    <joint
                                            name="fr3_joint6"
                                            axis="0 0 1"
                                            range="0.5445 4.5169"
                                            actuatorfrcrange="-12 12"
                                            armature="0.074"
                                            frictionloss="0.44"
                                        />
                    <geom
                                            mesh="link6_0"
                                            material="button_green"
                                            class="visual"
                                        />
                    <geom mesh="link6_1" material="white" class="visual" />
                    <geom mesh="link6_2" material="white" class="visual" />
                    <geom mesh="link6_3" material="gray" class="visual" />
                    <geom mesh="link6_4" material="button_red" class="visual" />
                    <geom mesh="link6_5" material="white" class="visual" />
                    <geom mesh="link6_6" material="black" class="visual" />
                    <geom
                                            mesh="link6_7"
                                            material="button_blue"
                                            class="visual"
                                        />
                    <!-- <geom name="fr3_link6_collision" class="collision" mesh="link6_coll"/> -->
                    <geom
                                            type="capsule"
                                            fromto="0 0 -0.08  0 0 0.0"
                                            size="0.06"
                                            class="collision"
                                        /> <!-- MJX -->
                    <body
                                            name="fr3_link7"
                                            pos="0.088 0 0"
                                            quat="1 1 0 0"
                                            gravcomp="1"
                                        >
                      <inertial
                                                pos="0.00452258 0.00862619 -0.0161633"
                                                quat="0.727579 0.0978688 -0.24906 0.63168"
                                                mass="0.627143"
                                                diaginertia="0.000223836 0.000223642 5.64132e-07"
                                            />
                      <joint
                                                name="fr3_joint7"
                                                axis="0 0 1"
                                                range="-3.0159 3.0159"
                                                actuatorfrcrange="-12 12"
                                                armature="0.074"
                                                frictionloss="0.248"
                                            />
                      <geom mesh="link7_0" material="black" class="visual" />
                      <geom mesh="link7_1" material="white" class="visual" />
                      <geom mesh="link7_2" material="white" class="visual" />
                      <geom mesh="link7_3" material="black" class="visual" />
                      <!-- <geom name="fr3_link7_collision" class="collision" mesh="link7_coll"/> -->
                      <geom
                                                type="capsule"
                                                fromto="0 0 -0.05  0 0 0.05"
                                                size="0.05"
                                                class="collision"
                                            /> <!-- MJX -->
                      <!-- <site name="attachment_site" pos="0 0 0.107"/> -->
                      <!-- This is basically link 8 from ROS -->
                      <body name="pusher" pos="0 0 0.107" gravcomp="1">
                        <!-- Long box as arm -->
                        <geom
                                                    type="box"
                                                    size="0.01 0.01 0.0625"
                                                    pos="0 0 0.0625"
                                                    rgba="0.0 0.0 0.0 1"
                                                />
                        <!-- Sphere at the tip of the box to act as end effector -->
                        <body name="ee_frame" pos="0 0 0.125" gravcomp="1">
                          <geom
                                                        type="sphere"
                                                        name="ee"
                                                        size="0.015"
                                                        pos="0 0 0"
                                                        rgba="0 0 0 1"
                                                        friction="0.1"
                                                        solref="0.03 1.1"
                                                        solimp="0.85 0.95 0.002 0.5 2"
                                                        condim="3"
                                                    />
                          <site
                                                        name="ee_site"
                                                        pos="0 0 0.0"
                                                        size="0.015"
                                                        rgba="0 0 0 1"
                                                    />
                        </body>
                      </body>

                    </body>
                  </body>
                </body>
              </body>
            </body>
          </body>
        </body>
      </body>
    </body>
  </worldbody>

  <!-- Limits taken from Franka Robot Description repo -->
  <actuator>
    <velocity
            class="fr3_vel"
            name="vel_joint1"
            joint="fr3_joint1"
            ctrlrange="-2.62  2.62"
        />
    <velocity
            class="fr3_vel"
            name="vel_joint2"
            joint="fr3_joint2"
            ctrlrange="-2.62  2.62"
        />
    <velocity
            class="fr3_vel"
            name="vel_joint3"
            joint="fr3_joint3"
            ctrlrange="-2.62  2.62"
        />
    <velocity
            class="fr3_vel"
            name="vel_joint4"
            joint="fr3_joint4"
            ctrlrange="-2.62  2.62"
        />
    <velocity
            class="fr3_vel"
            name="vel_joint5"
            joint="fr3_joint5"
            ctrlrange="-5.26  5.26"
        />
    <velocity
            class="fr3_vel"
            name="vel_joint6"
            joint="fr3_joint6"
            ctrlrange="-4.18  4.18"
        />
    <velocity
            class="fr3_vel"
            name="vel_joint7"
            joint="fr3_joint7"
            ctrlrange="-5.26  5.26"
        />
  </actuator>


  <contact>
    <exclude body1="fr3_link0" body2="fr3_link1" />
    <exclude body1="fr3_link1" body2="fr3_link2" />
    <exclude body1="fr3_link6" body2="fr3_link7" />
  </contact>

  <!-- Clashes with additional joint definitions in push T scene -->
  <!-- <keyframe>
    <key name="home" qpos="0 0 0 -1.57079 0 1.57079 -0.7853" ctrl="0 0 0 -1.57079 0 1.57079 -0.7853"/>
  </keyframe> -->

  <sensor>
    <framepos
            name="ee_frame_pos"
            objtype="body"
            objname="ee_frame"
            reftype="body"
            refname="world"
        />
    <framequat
            name="ee_frame_quat"
            objtype="body"
            objname="ee_frame"
            reftype="body"
            refname="world"
        />
  </sensor>

</mujoco>
